[2025-05-14T05:06:30.552+0000] {taskinstance.py:1159} INFO - Dependencies all met for dep_context=non-requeueable deps ti=<TaskInstance: upload_local_to_s3.upload_to_s3 manual__2025-05-14T05:06:29.501497+00:00 [queued]>
[2025-05-14T05:06:30.555+0000] {taskinstance.py:1159} INFO - Dependencies all met for dep_context=requeueable deps ti=<TaskInstance: upload_local_to_s3.upload_to_s3 manual__2025-05-14T05:06:29.501497+00:00 [queued]>
[2025-05-14T05:06:30.556+0000] {taskinstance.py:1361} INFO - Starting attempt 1 of 1
[2025-05-14T05:06:30.561+0000] {taskinstance.py:1382} INFO - Executing <Task(PythonOperator): upload_to_s3> on 2025-05-14 05:06:29.501497+00:00
[2025-05-14T05:06:30.564+0000] {standard_task_runner.py:57} INFO - Started process 5229 to run task
[2025-05-14T05:06:30.567+0000] {standard_task_runner.py:84} INFO - Running: ['***', 'tasks', 'run', 'upload_local_to_s3', 'upload_to_s3', 'manual__2025-05-14T05:06:29.501497+00:00', '--job-id', '8', '--raw', '--subdir', 'DAGS_FOLDER/etl_redfin_to_s3.py', '--cfg-path', '/tmp/tmpb18ucj5u']
[2025-05-14T05:06:30.569+0000] {standard_task_runner.py:85} INFO - Job 8: Subtask upload_to_s3
[2025-05-14T05:06:30.593+0000] {task_command.py:416} INFO - Running <TaskInstance: upload_local_to_s3.upload_to_s3 manual__2025-05-14T05:06:29.501497+00:00 [running]> on host 76d20adc2dd0
[2025-05-14T05:06:30.627+0000] {taskinstance.py:1662} INFO - Exporting env vars: AIRFLOW_CTX_DAG_OWNER='***' AIRFLOW_CTX_DAG_ID='upload_local_to_s3' AIRFLOW_CTX_TASK_ID='upload_to_s3' AIRFLOW_CTX_EXECUTION_DATE='2025-05-14T05:06:29.501497+00:00' AIRFLOW_CTX_TRY_NUMBER='1' AIRFLOW_CTX_DAG_RUN_ID='manual__2025-05-14T05:06:29.501497+00:00'
[2025-05-14T05:06:30.628+0000] {taskinstance.py:1937} ERROR - Task failed with exception
Traceback (most recent call last):
  File "/home/airflow/.local/lib/python3.10/site-packages/airflow/operators/python.py", line 192, in execute
    return_value = self.execute_callable()
  File "/home/airflow/.local/lib/python3.10/site-packages/airflow/operators/python.py", line 209, in execute_callable
    return self.python_callable(*self.op_args, **self.op_kwargs)
  File "/opt/airflow/dags/etl_redfin_to_s3.py", line 24, in upload_task
    upload_file_to_s3(local_file, bucket_name, s3_key)
NameError: name 'upload_file_to_s3' is not defined
[2025-05-14T05:06:30.634+0000] {taskinstance.py:1400} INFO - Marking task as FAILED. dag_id=upload_local_to_s3, task_id=upload_to_s3, execution_date=20250514T050629, start_date=20250514T050630, end_date=20250514T050630
[2025-05-14T05:06:30.639+0000] {standard_task_runner.py:104} ERROR - Failed to execute job 8 for task upload_to_s3 (name 'upload_file_to_s3' is not defined; 5229)
[2025-05-14T05:06:30.662+0000] {local_task_job_runner.py:228} INFO - Task exited with return code 1
[2025-05-14T05:06:30.670+0000] {taskinstance.py:2778} INFO - 0 downstream tasks scheduled from follow-on schedule check
